Workbook

Sheet Инструкция
B2: Модель TCO (Total Cost of Ownership) — кейс «Africa Delivery», горизонт 5 лет
B4: Зачем этот файл
B5: Задача | C5: Оценить полную стоимость владения выбранным архитектурным вариантом на 5 лет и использовать цифры как аргумент в ADR №1 («Выбор архитектурного стиля»).
B6: Как использовать | C6: Заполни один и тот же шаблон для каждого рассматриваемого варианта (например: модульный монолит / SOA / микросервисы) — сравнивать нужно итоги, а не ощущения.
B8: Цветовая легенда
B9: Синий текст на жёлтом фоне | C9: Ячейки для заполнения. Только их и редактируем.
B10: Чёрный текст | C10: Формулы. Не трогаем — пересчитаются сами.
B11: Зелёный текст | C11: Ссылка на лист «Допущения».
B13: Порядок работы
B14: Шаг 1 | C14: Лист «Допущения» → блок 1: вбить драйверы бизнеса по годам (активные пользователи, число заказов, средний чек). Из них считается GMV.
B15: Шаг 2 | C15: Лист «Допущения» → блок 2: финансовые допущения (инфляция, рост ФОТ, ставка дисконтирования, резерв, целевой SLO).
B16: Шаг 3 | C16: Лист «TCO» → в колонке «База, $/год (Год 1)» указать затраты первого года по каждой статье. Лишние статьи оставить пустыми, свои — дописать в свободные строки.
B17: Шаг 4 | C17: Лист «TCO» → в колонке «Драйвер роста» выбрать из выпадающего списка, от чего растёт статья: фикс / инфляция / ФОТ / пользователи / заказы / GMV. Годы 2–5 посчитаются сами.
B18: Шаг 5 | C18: Проверьте ключевые показатели на каждом листе TCO: совокупные затраты за пять лет, приведённую стоимость затрат, стоимость одного заказа и соблюдение лимита финансового директора на облако ($5 000 в месяц).
B20: Что важно не забыть в этом кейсе
B21: Бюджет CFO | C21: $5 000 в месяц на облачную инфраструктуру при запуске. Если затраты первого года превышают лимит, укажите, от чего отказываетесь, либо запросите исключение у финансового директора.
B22: Цена простоя | C22: Инвестор оценивает минуту простоя в $12 000. Целевой SLO 99,99% = 52,6 мин/год ≈ $631k. Этот риск считается отдельным блоком — сравни его со стоимостью резервирования.
B23: Транзакционные расходы | C23: Комиссии M-Pesa / Flutterwave / Paystack, SMS и WhatsApp растут с GMV и числом заказов и на горизонте 5 лет обычно обгоняют инфраструктуру. Не забудь их — это типичная ошибка.
B24: Сравнение вариантов | C24: Транзакционные расходы (блок 3) почти одинаковы для любой архитектуры — это pass-through от оборота. Варианты архитектуры сравнивай по блокам 1, 2, 4 и 6.
B25: Разовые затраты | C25: Комплаенс-аудит NDPR/POPIA, пентест, миграция — если статья возникает не каждый год, просто перезапиши формулу в нужной ячейке года числом (и покрась в синий).
B26: Люди | C26: ФОТ команды — обычно самая крупная статья TCO. Микросервисы дешевле в масштабировании, но дороже в эксплуатации: это должно быть видно в цифрах, а не только в тексте ADR.
B28: Все числа в файле — примеры для демонстрации формата. Замени их своими оценками и укажи источник в колонке «Комментарий / источник».

Sheet A-Допущения
B2: Допущения модели TCO — Africa Delivery
B3: Заполняются только ячейки с жёлтой заливкой. Все числа ниже — пример, заменить своими.
B5: 1. Драйверы бизнеса — заполнить
B6: Показатель | C6: Год 1 | D6: Год 2 | E6: Год 3 | F6: Год 4 | G6: Год 5 | H6: Комментарий / источник
B7: Активные пользователи (на конец года) | C7: 1000000 | D7: 2000000 | E7: 4000000 | F7: 7000000 | G7: 10000000 | H7: Цель кейса: 1 млн активных пользователей в первый год; расчётный сценарий — 10 млн.
B8: Число заказов в год | C8: 300000 | D8: 1800000 | E8: 6000000 | F8: 12000000 | G8: 18000000 | H8: От 300 тыс. до 18 млн заказов в год; единый сценарий спроса для всех вариантов.
B9: Средний чек (AOV), $ | C9: 25 | D9: 26 | E9: 27 | F9: 28 | G9: 29 | H9: Плановая оценка среднего чека; доллары США 2026 года; точность ±30%.
B10: GMV, $ в год (расчёт) | C10: =C8*C9 -> 7500000 | D10: =D8*D9 -> 46800000 | E10: =E8*E9 -> 162000000 | F10: =F8*F9 -> 336000000 | G10: =G8*G9 -> 522000000 | H10: Расчёт: число заказов за год × средний чек.
B12: 2. Финансовые допущения — заполнить
B13: Параметр | C13: Значение | H13: Комментарий / источник
B14: Инфляция затрат, % в год | C14: 0.08 | H14: Плановое допущение из модели задания 2; применяется к затратам, растущим с инфляцией.
B15: Рост ФОТ, % в год | C15: 0.12 | H15: Плановое допущение из модели задания 2; применяется к фонду оплаты труда.
B16: Ставка дисконтирования, % в год | C16: 0.2 | H16: Ставка дисконтирования для стартапа с высоким уровнем риска.
B17: Резерв на непредвиденное (contingency), % | C17: 0.15 | H17: Резерв начисляется на сумму блоков 1–5.
B18: Бюджет CFO на облако, $/мес | C18: 5000 | H18: Письмо финансового директора, п. 1: жёсткий лимит $5 000 в месяц.
B19: Стоимость минуты простоя, $ | C19: 12000 | H19: Оценка инвестора; используется для анализа чувствительности, а не как подтверждённый ожидаемый ущерб.
B20: Целевой SLO (доступность), % | C20: 0.9995 | H20: Плановый целевой уровень обслуживания для инициации платежа из задания 3; для каталога и уведомлений установлены отдельные показатели.
B21: Учитывать стоимость простоя в TCO (1 — да, 0 — нет) | C21: 1 | H21: Значение 1 сохраняет оценку потерь от простоя отдельно от прямых затрат.
B23: 3. Индексы роста — расчёт, не редактировать
B24: Драйвер | C24: Год 1 | D24: Год 2 | E24: Год 3 | F24: Год 4 | G24: Год 5 | H24: Как считается
B25: мощность | C25: =SQRT(C7/$C$7) -> 1 | D25: =SQRT(D7/$C$7) -> 1.4142136 | E25: =SQRT(E7/$C$7) -> 2 | F25: =SQRT(F7/$C$7) -> 2.6457513 | G25: =SQRT(G7/$C$7) -> 3.1622777 | H25: Квадратный корень из роста активных пользователей; учитывает экономию от масштаба инфраструктуры.
B26: нагрузка заказов | C26: =SQRT(C8/$C$8) -> 1 | D26: =SQRT(D8/$C$8) -> 2.4494897 | E26: =SQRT(E8/$C$8) -> 4.472136 | F26: =SQRT(F8/$C$8) -> 6.3245553 | G26: =SQRT(G8/$C$8) -> 7.7459667 | H26: Квадратный корень из роста числа заказов; применяется к трафику и асинхронной обработке.
B27: инфляция | C27: =1 -> 1 | D27: =C27*(1+$C$14) -> 1.08 | E27: =D27*(1+$C$14) -> 1.1664 | F27: =E27*(1+$C$14) -> 1.259712 | G27: =F27*(1+$C$14) -> 1.360489 | H27: Год N = предыдущий год × (1 + инфляция затрат).
B28: ФОТ | C28: =1 -> 1 | D28: =C28*(1+$C$15) -> 1.12 | E28: =D28*(1+$C$15) -> 1.2544 | F28: =E28*(1+$C$15) -> 1.404928 | G28: =F28*(1+$C$15) -> 1.5735194 | H28: Год N = предыдущий год × (1 + рост ФОТ).
B29: заказы | C29: =C8/$C$8 -> 1 | D29: =D8/$C$8 -> 6 | E29: =E8/$C$8 -> 20 | F29: =F8/$C$8 -> 40 | G29: =G8/$C$8 -> 60 | H29: Линейная зависимость от числа заказов для поштучно тарифицируемых услуг партнёров.
B30: оборот (GMV) | C30: =C10/$C$10 -> 1 | D30: =D10/$C$10 -> 6.24 | E30: =E10/$C$10 -> 21.6 | F30: =F10/$C$10 -> 44.8 | G30: =G10/$C$10 -> 69.6 | H30: Линейная зависимость комиссий платёжных провайдеров от оборота.
B32: Заданные показатели мощности растут пропорционально квадратному корню из нагрузки и учитывают экономию от масштаба; транзакционные расходы растут линейно с числом заказов или оборотом.

Sheet A-TCO
B2: TCO на 5 лет — Africa Delivery
B3: Заполняем колонки «Драйвер роста» и «База, $/год (Год 1)». Годы 1–5 считаются автоматически.
B5: Статья затрат | C5: Драйвер роста | D5: База, $/год (Год 1) | E5: Год 1 | F5: Год 2 | G5: Год 3 | H5: Год 4 | I5: Год 5 | J5: Итого 5 лет | K5: Доля | L5: Комментарий / источник
B6: БЛОК 1. Облачная инфраструктура (OpEx)
B7: Вычислительные ресурсы и контейнеры | C7: мощность | D7: 14400 | E7: =IF($D7="","",$D7*INDEX('A-Допущения'!$C$25:$G$30,MATCH($C7,'A-Допущения'!$B$25:$B$30,0),1)) -> 14400 | F7: =IF($D7="","",$D7*INDEX('A-Допущения'!$C$25:$G$30,MATCH($C7,'A-Допущения'!$B$25:$B$30,0),2)) -> 20364.675 | G7: =IF($D7="","",$D7*INDEX('A-Допущения'!$C$25:$G$30,MATCH($C7,'A-Допущения'!$B$25:$B$30,0),3)) -> 28800 | H7: =IF($D7="","",$D7*INDEX('A-Допущения'!$C$25:$G$30,MATCH($C7,'A-Допущения'!$B$25:$B$30,0),4)) -> 38098.819 | I7: =IF($D7="","",$D7*INDEX('A-Допущения'!$C$25:$G$30,MATCH($C7,'A-Допущения'!$B$25:$B$30,0),5)) -> 45536.798 | J7: =SUM(E7:I7) -> 147200.29 | L7: Экземпляры модульного монолита без локального состояния; предварительная оценка.
B8: Управляемая СУБД PostgreSQL | C8: мощность | D8: 9600 | E8: =IF($D8="","",$D8*INDEX('A-Допущения'!$C$25:$G$30,MATCH($C8,'A-Допущения'!$B$25:$B$30,0),1)) -> 9600 | F8: =IF($D8="","",$D8*INDEX('A-Допущения'!$C$25:$G$30,MATCH($C8,'A-Допущения'!$B$25:$B$30,0),2)) -> 13576.45 | G8: =IF($D8="","",$D8*INDEX('A-Допущения'!$C$25:$G$30,MATCH($C8,'A-Допущения'!$B$25:$B$30,0),3)) -> 19200 | H8: =IF($D8="","",$D8*INDEX('A-Допущения'!$C$25:$G$30,MATCH($C8,'A-Допущения'!$B$25:$B$30,0),4)) -> 25399.213 | I8: =IF($D8="","",$D8*INDEX('A-Допущения'!$C$25:$G$30,MATCH($C8,'A-Допущения'!$B$25:$B$30,0),5)) -> 30357.866 | J8: =SUM(E8:I8) -> 98133.528 | L8: Отказоустойчивая управляемая СУБД PostgreSQL; предварительная оценка.
B9: Объектное хранилище и резервные копии | C9: мощность | D9: 2400 | E9: =IF($D9="","",$D9*INDEX('A-Допущения'!$C$25:$G$30,MATCH($C9,'A-Допущения'!$B$25:$B$30,0),1)) -> 2400 | F9: =IF($D9="","",$D9*INDEX('A-Допущения'!$C$25:$G$30,MATCH($C9,'A-Допущения'!$B$25:$B$30,0),2)) -> 3394.1125 | G9: =IF($D9="","",$D9*INDEX('A-Допущения'!$C$25:$G$30,MATCH($C9,'A-Допущения'!$B$25:$B$30,0),3)) -> 4800 | H9: =IF($D9="","",$D9*INDEX('A-Допущения'!$C$25:$G$30,MATCH($C9,'A-Допущения'!$B$25:$B$30,0),4)) -> 6349.8031 | I9: =IF($D9="","",$D9*INDEX('A-Допущения'!$C$25:$G$30,MATCH($C9,'A-Допущения'!$B$25:$B$30,0),5)) -> 7589.4664 | J9: =SUM(E9:I9) -> 24533.382 | L9: 5 000 товарных позиций при запуске и защищённые резервные копии.
B10: Сеть доставки содержимого (CDN) и исходящий трафик | C10: нагрузка заказов | D10: 6000 | E10: =IF($D10="","",$D10*INDEX('A-Допущения'!$C$25:$G$30,MATCH($C10,'A-Допущения'!$B$25:$B$30,0),1)) -> 6000 | F10: =IF($D10="","",$D10*INDEX('A-Допущения'!$C$25:$G$30,MATCH($C10,'A-Допущения'!$B$25:$B$30,0),2)) -> 14696.938 | G10: =IF($D10="","",$D10*INDEX('A-Допущения'!$C$25:$G$30,MATCH($C10,'A-Допущения'!$B$25:$B$30,0),3)) -> 26832.816 | H10: =IF($D10="","",$D10*INDEX('A-Допущения'!$C$25:$G$30,MATCH($C10,'A-Допущения'!$B$25:$B$30,0),4)) -> 37947.332 | I10: =IF($D10="","",$D10*INDEX('A-Допущения'!$C$25:$G$30,MATCH($C10,'A-Допущения'!$B$25:$B$30,0),5)) -> 46475.8 | J10: =SUM(E10:I10) -> 131952.89 | L10: Изображения WebP/AVIF, оптимизированные для мобильных сетей.
B11: Очередь и фоновые задания | C11: нагрузка заказов | D11: 1200 | E11: =IF($D11="","",$D11*INDEX('A-Допущения'!$C$25:$G$30,MATCH($C11,'A-Допущения'!$B$25:$B$30,0),1)) -> 1200 | F11: =IF($D11="","",$D11*INDEX('A-Допущения'!$C$25:$G$30,MATCH($C11,'A-Допущения'!$B$25:$B$30,0),2)) -> 2939.3877 | G11: =IF($D11="","",$D11*INDEX('A-Допущения'!$C$25:$G$30,MATCH($C11,'A-Допущения'!$B$25:$B$30,0),3)) -> 5366.5631 | H11: =IF($D11="","",$D11*INDEX('A-Допущения'!$C$25:$G$30,MATCH($C11,'A-Допущения'!$B$25:$B$30,0),4)) -> 7589.4664 | I11: =IF($D11="","",$D11*INDEX('A-Допущения'!$C$25:$G$30,MATCH($C11,'A-Допущения'!$B$25:$B$30,0),5)) -> 9295.16 | J11: =SUM(E11:I11) -> 26390.577 | L11: Управляемая очередь либо фоновые задания на основе базы данных.
B12: Тёплый резерв для аварийного восстановления | C12: мощность | D12: 6000 | E12: =IF($D12="","",$D12*INDEX('A-Допущения'!$C$25:$G$30,MATCH($C12,'A-Допущения'!$B$25:$B$30,0),1)) -> 6000 | F12: =IF($D12="","",$D12*INDEX('A-Допущения'!$C$25:$G$30,MATCH($C12,'A-Допущения'!$B$25:$B$30,0),2)) -> 8485.2814 | G12: =IF($D12="","",$D12*INDEX('A-Допущения'!$C$25:$G$30,MATCH($C12,'A-Допущения'!$B$25:$B$30,0),3)) -> 12000 | H12: =IF($D12="","",$D12*INDEX('A-Допущения'!$C$25:$G$30,MATCH($C12,'A-Допущения'!$B$25:$B$30,0),4)) -> 15874.508 | I12: =IF($D12="","",$D12*INDEX('A-Допущения'!$C$25:$G$30,MATCH($C12,'A-Допущения'!$B$25:$B$30,0),5)) -> 18973.666 | J12: =SUM(E12:I12) -> 61333.455 | L12: Резервные копии, восстановление и тёплые вычислительные ресурсы.
B13: Локальное размещение данных в Нигерии | C13: инфляция | D13: 9000 | E13: =IF($D13="","",$D13*INDEX('A-Допущения'!$C$25:$G$30,MATCH($C13,'A-Допущения'!$B$25:$B$30,0),1)) -> 9000 | F13: =IF($D13="","",$D13*INDEX('A-Допущения'!$C$25:$G$30,MATCH($C13,'A-Допущения'!$B$25:$B$30,0),2)) -> 9720 | G13: =IF($D13="","",$D13*INDEX('A-Допущения'!$C$25:$G$30,MATCH($C13,'A-Допущения'!$B$25:$B$30,0),3)) -> 10497.6 | H13: =IF($D13="","",$D13*INDEX('A-Допущения'!$C$25:$G$30,MATCH($C13,'A-Допущения'!$B$25:$B$30,0),4)) -> 11337.408 | I13: =IF($D13="","",$D13*INDEX('A-Допущения'!$C$25:$G$30,MATCH($C13,'A-Допущения'!$B$25:$B$30,0),5)) -> 12244.401 | J13: =SUM(E13:I13) -> 52799.409 | L13: Плановый резерв; требуется коммерческое предложение провайдера из задания 4.
C14: инфляция | E14: =IF($D14="","",$D14*INDEX('A-Допущения'!$C$25:$G$30,MATCH($C14,'A-Допущения'!$B$25:$B$30,0),1)) | F14: =IF($D14="","",$D14*INDEX('A-Допущения'!$C$25:$G$30,MATCH($C14,'A-Допущения'!$B$25:$B$30,0),2)) | G14: =IF($D14="","",$D14*INDEX('A-Допущения'!$C$25:$G$30,MATCH($C14,'A-Допущения'!$B$25:$B$30,0),3)) | H14: =IF($D14="","",$D14*INDEX('A-Допущения'!$C$25:$G$30,MATCH($C14,'A-Допущения'!$B$25:$B$30,0),4)) | I14: =IF($D14="","",$D14*INDEX('A-Допущения'!$C$25:$G$30,MATCH($C14,'A-Допущения'!$B$25:$B$30,0),5)) | J14: =SUM(E14:I14) -> 0
B15: Итого по блоку | E15: =SUM(E7:E14) -> 48600 | F15: =SUM(F7:F14) -> 73176.846 | G15: =SUM(G7:G14) -> 107496.98 | H15: =SUM(H7:H14) -> 142596.55 | I15: =SUM(I7:I14) -> 170473.16 | J15: =SUM(E15:I15) -> 542343.53 | K15: =IFERROR(J15/$J$51,0) -> 0.012759451
B17: БЛОК 2. Лицензии, SaaS и инструменты
B18: Наблюдаемость | C18: мощность | D18: 2400 | E18: =IF($D18="","",$D18*INDEX('A-Допущения'!$C$25:$G$30,MATCH($C18,'A-Допущения'!$B$25:$B$30,0),1)) -> 2400 | F18: =IF($D18="","",$D18*INDEX('A-Допущения'!$C$25:$G$30,MATCH($C18,'A-Допущения'!$B$25:$B$30,0),2)) -> 3394.1125 | G18: =IF($D18="","",$D18*INDEX('A-Допущения'!$C$25:$G$30,MATCH($C18,'A-Допущения'!$B$25:$B$30,0),3)) -> 4800 | H18: =IF($D18="","",$D18*INDEX('A-Допущения'!$C$25:$G$30,MATCH($C18,'A-Допущения'!$B$25:$B$30,0),4)) -> 6349.8031 | I18: =IF($D18="","",$D18*INDEX('A-Допущения'!$C$25:$G$30,MATCH($C18,'A-Допущения'!$B$25:$B$30,0),5)) -> 7589.4664 | J18: =SUM(E18:I18) -> 24533.382 | L18: Решения с открытым исходным кодом и ограниченный срок хранения телеметрии.
B19: Непрерывная интеграция и доставка, репозиторий, артефакты | C19: инфляция | D19: 1200 | E19: =IF($D19="","",$D19*INDEX('A-Допущения'!$C$25:$G$30,MATCH($C19,'A-Допущения'!$B$25:$B$30,0),1)) -> 1200 | F19: =IF($D19="","",$D19*INDEX('A-Допущения'!$C$25:$G$30,MATCH($C19,'A-Допущения'!$B$25:$B$30,0),2)) -> 1296 | G19: =IF($D19="","",$D19*INDEX('A-Допущения'!$C$25:$G$30,MATCH($C19,'A-Допущения'!$B$25:$B$30,0),3)) -> 1399.68 | H19: =IF($D19="","",$D19*INDEX('A-Допущения'!$C$25:$G$30,MATCH($C19,'A-Допущения'!$B$25:$B$30,0),4)) -> 1511.6544 | I19: =IF($D19="","",$D19*INDEX('A-Допущения'!$C$25:$G$30,MATCH($C19,'A-Допущения'!$B$25:$B$30,0),5)) -> 1632.5868 | J19: =SUM(E19:I19) -> 7039.9212 | L19: Расчёт для команды из шести человек.
B20: Безопасность: межсетевой экран веб-приложений и секреты | C20: мощность | D20: 3600 | E20: =IF($D20="","",$D20*INDEX('A-Допущения'!$C$25:$G$30,MATCH($C20,'A-Допущения'!$B$25:$B$30,0),1)) -> 3600 | F20: =IF($D20="","",$D20*INDEX('A-Допущения'!$C$25:$G$30,MATCH($C20,'A-Допущения'!$B$25:$B$30,0),2)) -> 5091.1688 | G20: =IF($D20="","",$D20*INDEX('A-Допущения'!$C$25:$G$30,MATCH($C20,'A-Допущения'!$B$25:$B$30,0),3)) -> 7200 | H20: =IF($D20="","",$D20*INDEX('A-Допущения'!$C$25:$G$30,MATCH($C20,'A-Допущения'!$B$25:$B$30,0),4)) -> 9524.7047 | I20: =IF($D20="","",$D20*INDEX('A-Допущения'!$C$25:$G$30,MATCH($C20,'A-Допущения'!$B$25:$B$30,0),5)) -> 11384.2 | J20: =SUM(E20:I20) -> 36800.073 | L20: Управляемые средства защиты.
B21: Фиксированная плата за WhatsApp Business API | C21: инфляция | D21: 1200 | E21: =IF($D21="","",$D21*INDEX('A-Допущения'!$C$25:$G$30,MATCH($C21,'A-Допущения'!$B$25:$B$30,0),1)) -> 1200 | F21: =IF($D21="","",$D21*INDEX('A-Допущения'!$C$25:$G$30,MATCH($C21,'A-Допущения'!$B$25:$B$30,0),2)) -> 1296 | G21: =IF($D21="","",$D21*INDEX('A-Допущения'!$C$25:$G$30,MATCH($C21,'A-Допущения'!$B$25:$B$30,0),3)) -> 1399.68 | H21: =IF($D21="","",$D21*INDEX('A-Допущения'!$C$25:$G$30,MATCH($C21,'A-Допущения'!$B$25:$B$30,0),4)) -> 1511.6544 | I21: =IF($D21="","",$D21*INDEX('A-Допущения'!$C$25:$G$30,MATCH($C21,'A-Допущения'!$B$25:$B$30,0),5)) -> 1632.5868 | J21: =SUM(E21:I21) -> 7039.9212 | L21: Постоянная плата; переменные расходы учтены в блоке 3.
B22: Прочие инструменты разработки | C22: инфляция | D22: 1200 | E22: =IF($D22="","",$D22*INDEX('A-Допущения'!$C$25:$G$30,MATCH($C22,'A-Допущения'!$B$25:$B$30,0),1)) -> 1200 | F22: =IF($D22="","",$D22*INDEX('A-Допущения'!$C$25:$G$30,MATCH($C22,'A-Допущения'!$B$25:$B$30,0),2)) -> 1296 | G22: =IF($D22="","",$D22*INDEX('A-Допущения'!$C$25:$G$30,MATCH($C22,'A-Допущения'!$B$25:$B$30,0),3)) -> 1399.68 | H22: =IF($D22="","",$D22*INDEX('A-Допущения'!$C$25:$G$30,MATCH($C22,'A-Допущения'!$B$25:$B$30,0),4)) -> 1511.6544 | I22: =IF($D22="","",$D22*INDEX('A-Допущения'!$C$25:$G$30,MATCH($C22,'A-Допущения'!$B$25:$B$30,0),5)) -> 1632.5868 | J22: =SUM(E22:I22) -> 7039.9212 | L22: Средства управления задачами, проектирования и совместной работы.
C23: инфляция | E23: =IF($D23="","",$D23*INDEX('A-Допущения'!$C$25:$G$30,MATCH($C23,'A-Допущения'!$B$25:$B$30,0),1)) | F23: =IF($D23="","",$D23*INDEX('A-Допущения'!$C$25:$G$30,MATCH($C23,'A-Допущения'!$B$25:$B$30,0),2)) | G23: =IF($D23="","",$D23*INDEX('A-Допущения'!$C$25:$G$30,MATCH($C23,'A-Допущения'!$B$25:$B$30,0),3)) | H23: =IF($D23="","",$D23*INDEX('A-Допущения'!$C$25:$G$30,MATCH($C23,'A-Допущения'!$B$25:$B$30,0),4)) | I23: =IF($D23="","",$D23*INDEX('A-Допущения'!$C$25:$G$30,MATCH($C23,'A-Допущения'!$B$25:$B$30,0),5)) | J23: =SUM(E23:I23) -> 0
B24: Итого по блоку | E24: =SUM(E18:E23) -> 9600 | F24: =SUM(F18:F23) -> 12373.281 | G24: =SUM(G18:G23) -> 16199.04 | H24: =SUM(H18:H23) -> 20409.471 | I24: =SUM(I18:I23) -> 23871.426 | J24: =SUM(E24:I24) -> 82453.219 | K24: =IFERROR(J24/$J$51,0) -> 0.0019398366
B26: БЛОК 3. Транзакционные расходы (Buy / Partner)
B27: Комиссии платёжных провайдеров | C27: оборот (GMV) | D27: 187500 | E27: =IF($D27="","",$D27*INDEX('A-Допущения'!$C$25:$G$30,MATCH($C27,'A-Допущения'!$B$25:$B$30,0),1)) -> 187500 | F27: =IF($D27="","",$D27*INDEX('A-Допущения'!$C$25:$G$30,MATCH($C27,'A-Допущения'!$B$25:$B$30,0),2)) -> 1170000 | G27: =IF($D27="","",$D27*INDEX('A-Допущения'!$C$25:$G$30,MATCH($C27,'A-Допущения'!$B$25:$B$30,0),3)) -> 4050000 | H27: =IF($D27="","",$D27*INDEX('A-Допущения'!$C$25:$G$30,MATCH($C27,'A-Допущения'!$B$25:$B$30,0),4)) -> 8400000 | I27: =IF($D27="","",$D27*INDEX('A-Допущения'!$C$25:$G$30,MATCH($C27,'A-Допущения'!$B$25:$B$30,0),5)) -> 13050000 | J27: =SUM(E27:I27) -> 26857500 | L27: 2,5% оборота первого года; письмо финансового директора, п. 6.
B28: SMS-уведомления | C28: заказы | D28: 12000 | E28: =IF($D28="","",$D28*INDEX('A-Допущения'!$C$25:$G$30,MATCH($C28,'A-Допущения'!$B$25:$B$30,0),1)) -> 12000 | F28: =IF($D28="","",$D28*INDEX('A-Допущения'!$C$25:$G$30,MATCH($C28,'A-Допущения'!$B$25:$B$30,0),2)) -> 72000 | G28: =IF($D28="","",$D28*INDEX('A-Допущения'!$C$25:$G$30,MATCH($C28,'A-Допущения'!$B$25:$B$30,0),3)) -> 240000 | H28: =IF($D28="","",$D28*INDEX('A-Допущения'!$C$25:$G$30,MATCH($C28,'A-Допущения'!$B$25:$B$30,0),4)) -> 480000 | I28: =IF($D28="","",$D28*INDEX('A-Допущения'!$C$25:$G$30,MATCH($C28,'A-Допущения'!$B$25:$B$30,0),5)) -> 720000 | J28: =SUM(E28:I28) -> 1524000 | L28: $0,04 на заказ; допущение модели задания 2.
B29: Сообщения WhatsApp | C29: заказы | D29: 9000 | E29: =IF($D29="","",$D29*INDEX('A-Допущения'!$C$25:$G$30,MATCH($C29,'A-Допущения'!$B$25:$B$30,0),1)) -> 9000 | F29: =IF($D29="","",$D29*INDEX('A-Допущения'!$C$25:$G$30,MATCH($C29,'A-Допущения'!$B$25:$B$30,0),2)) -> 54000 | G29: =IF($D29="","",$D29*INDEX('A-Допущения'!$C$25:$G$30,MATCH($C29,'A-Допущения'!$B$25:$B$30,0),3)) -> 180000 | H29: =IF($D29="","",$D29*INDEX('A-Допущения'!$C$25:$G$30,MATCH($C29,'A-Допущения'!$B$25:$B$30,0),4)) -> 360000 | I29: =IF($D29="","",$D29*INDEX('A-Допущения'!$C$25:$G$30,MATCH($C29,'A-Допущения'!$B$25:$B$30,0),5)) -> 540000 | J29: =SUM(E29:I29) -> 1143000 | L29: $0,03 на заказ; допущение модели задания 2.
B30: Комиссии за интеграцию с логистическими партнёрами | C30: заказы | D30: 30000 | E30: =IF($D30="","",$D30*INDEX('A-Допущения'!$C$25:$G$30,MATCH($C30,'A-Допущения'!$B$25:$B$30,0),1)) -> 30000 | F30: =IF($D30="","",$D30*INDEX('A-Допущения'!$C$25:$G$30,MATCH($C30,'A-Допущения'!$B$25:$B$30,0),2)) -> 180000 | G30: =IF($D30="","",$D30*INDEX('A-Допущения'!$C$25:$G$30,MATCH($C30,'A-Допущения'!$B$25:$B$30,0),3)) -> 600000 | H30: =IF($D30="","",$D30*INDEX('A-Допущения'!$C$25:$G$30,MATCH($C30,'A-Допущения'!$B$25:$B$30,0),4)) -> 1200000 | I30: =IF($D30="","",$D30*INDEX('A-Допущения'!$C$25:$G$30,MATCH($C30,'A-Допущения'!$B$25:$B$30,0),5)) -> 1800000 | J30: =SUM(E30:I30) -> 3810000 | L30: $0,10 на заказ; стоимость курьерской доставки не включена.
C31: инфляция | E31: =IF($D31="","",$D31*INDEX('A-Допущения'!$C$25:$G$30,MATCH($C31,'A-Допущения'!$B$25:$B$30,0),1)) | F31: =IF($D31="","",$D31*INDEX('A-Допущения'!$C$25:$G$30,MATCH($C31,'A-Допущения'!$B$25:$B$30,0),2)) | G31: =IF($D31="","",$D31*INDEX('A-Допущения'!$C$25:$G$30,MATCH($C31,'A-Допущения'!$B$25:$B$30,0),3)) | H31: =IF($D31="","",$D31*INDEX('A-Допущения'!$C$25:$G$30,MATCH($C31,'A-Допущения'!$B$25:$B$30,0),4)) | I31: =IF($D31="","",$D31*INDEX('A-Допущения'!$C$25:$G$30,MATCH($C31,'A-Допущения'!$B$25:$B$30,0),5)) | J31: =SUM(E31:I31) -> 0
B32: Итого по блоку | E32: =SUM(E27:E31) -> 238500 | F32: =SUM(F27:F31) -> 1476000 | G32: =SUM(G27:G31) -> 5070000 | H32: =SUM(H27:H31) -> 10440000 | I32: =SUM(I27:I31) -> 16110000 | J32: =SUM(E32:I32) -> 33334500 | K32: =IFERROR(J32/$J$51,0) -> 0.78424451
B34: БЛОК 4. Команда (ФОТ)
B35: Разработка (4 специалиста) | C35: ФОТ | D35: 240000 | E35: =IF($D35="","",$D35*INDEX('A-Допущения'!$C$25:$G$30,MATCH($C35,'A-Допущения'!$B$25:$B$30,0),1)) -> 240000 | F35: =IF($D35="","",$D35*INDEX('A-Допущения'!$C$25:$G$30,MATCH($C35,'A-Допущения'!$B$25:$B$30,0),2)) -> 268800 | G35: =IF($D35="","",$D35*INDEX('A-Допущения'!$C$25:$G$30,MATCH($C35,'A-Допущения'!$B$25:$B$30,0),3)) -> 301056 | H35: =IF($D35="","",$D35*INDEX('A-Допущения'!$C$25:$G$30,MATCH($C35,'A-Допущения'!$B$25:$B$30,0),4)) -> 337182.72 | I35: =IF($D35="","",$D35*INDEX('A-Допущения'!$C$25:$G$30,MATCH($C35,'A-Допущения'!$B$25:$B$30,0),5)) -> 377644.65 | J35: =SUM(E35:I35) -> 1524683.4 | L35: 4 × $60 тыс. полной годовой стоимости специалиста.
B36: Эксплуатация и надёжность (1 специалист) | C36: ФОТ | D36: 60000 | E36: =IF($D36="","",$D36*INDEX('A-Допущения'!$C$25:$G$30,MATCH($C36,'A-Допущения'!$B$25:$B$30,0),1)) -> 60000 | F36: =IF($D36="","",$D36*INDEX('A-Допущения'!$C$25:$G$30,MATCH($C36,'A-Допущения'!$B$25:$B$30,0),2)) -> 67200 | G36: =IF($D36="","",$D36*INDEX('A-Допущения'!$C$25:$G$30,MATCH($C36,'A-Допущения'!$B$25:$B$30,0),3)) -> 75264 | H36: =IF($D36="","",$D36*INDEX('A-Допущения'!$C$25:$G$30,MATCH($C36,'A-Допущения'!$B$25:$B$30,0),4)) -> 84295.68 | I36: =IF($D36="","",$D36*INDEX('A-Допущения'!$C$25:$G$30,MATCH($C36,'A-Допущения'!$B$25:$B$30,0),5)) -> 94411.162 | J36: =SUM(E36:I36) -> 381170.84 | L36: 1 × $60 тыс. полной годовой стоимости специалиста.
B37: Тестирование, поддержка и дежурство (1 специалист) | C37: ФОТ | D37: 60000 | E37: =IF($D37="","",$D37*INDEX('A-Допущения'!$C$25:$G$30,MATCH($C37,'A-Допущения'!$B$25:$B$30,0),1)) -> 60000 | F37: =IF($D37="","",$D37*INDEX('A-Допущения'!$C$25:$G$30,MATCH($C37,'A-Допущения'!$B$25:$B$30,0),2)) -> 67200 | G37: =IF($D37="","",$D37*INDEX('A-Допущения'!$C$25:$G$30,MATCH($C37,'A-Допущения'!$B$25:$B$30,0),3)) -> 75264 | H37: =IF($D37="","",$D37*INDEX('A-Допущения'!$C$25:$G$30,MATCH($C37,'A-Допущения'!$B$25:$B$30,0),4)) -> 84295.68 | I37: =IF($D37="","",$D37*INDEX('A-Допущения'!$C$25:$G$30,MATCH($C37,'A-Допущения'!$B$25:$B$30,0),5)) -> 94411.162 | J37: =SUM(E37:I37) -> 381170.84 | L37: 1 × $60 тыс. полной годовой стоимости специалиста.
B38: Архитектура и управление | C38: ФОТ | D38: 90000 | E38: =IF($D38="","",$D38*INDEX('A-Допущения'!$C$25:$G$30,MATCH($C38,'A-Допущения'!$B$25:$B$30,0),1)) -> 90000 | F38: =IF($D38="","",$D38*INDEX('A-Допущения'!$C$25:$G$30,MATCH($C38,'A-Допущения'!$B$25:$B$30,0),2)) -> 100800 | G38: =IF($D38="","",$D38*INDEX('A-Допущения'!$C$25:$G$30,MATCH($C38,'A-Допущения'!$B$25:$B$30,0),3)) -> 112896 | H38: =IF($D38="","",$D38*INDEX('A-Допущения'!$C$25:$G$30,MATCH($C38,'A-Допущения'!$B$25:$B$30,0),4)) -> 126443.52 | I38: =IF($D38="","",$D38*INDEX('A-Допущения'!$C$25:$G$30,MATCH($C38,'A-Допущения'!$B$25:$B$30,0),5)) -> 141616.74 | J38: =SUM(E38:I38) -> 571756.26 | L38: Доля затрат на технического директора, архитектора и управление продуктом.
C39: инфляция | E39: =IF($D39="","",$D39*INDEX('A-Допущения'!$C$25:$G$30,MATCH($C39,'A-Допущения'!$B$25:$B$30,0),1)) | F39: =IF($D39="","",$D39*INDEX('A-Допущения'!$C$25:$G$30,MATCH($C39,'A-Допущения'!$B$25:$B$30,0),2)) | G39: =IF($D39="","",$D39*INDEX('A-Допущения'!$C$25:$G$30,MATCH($C39,'A-Допущения'!$B$25:$B$30,0),3)) | H39: =IF($D39="","",$D39*INDEX('A-Допущения'!$C$25:$G$30,MATCH($C39,'A-Допущения'!$B$25:$B$30,0),4)) | I39: =IF($D39="","",$D39*INDEX('A-Допущения'!$C$25:$G$30,MATCH($C39,'A-Допущения'!$B$25:$B$30,0),5)) | J39: =SUM(E39:I39) -> 0
B40: Итого по блоку | E40: =SUM(E35:E39) -> 450000 | F40: =SUM(F35:F39) -> 504000 | G40: =SUM(G35:G39) -> 564480 | H40: =SUM(H35:H39) -> 632217.6 | I40: =SUM(I35:I39) -> 708083.71 | J40: =SUM(E40:I40) -> 2858781.3 | K40: =IFERROR(J40/$J$51,0) -> 0.067257152
B42: БЛОК 5. Разовые затраты и комплаенс
B43: Юридический аудит и проверка соответствия требованиям | C43: инфляция | D43: 25000 | E43: =IF($D43="","",$D43*INDEX('A-Допущения'!$C$25:$G$30,MATCH($C43,'A-Допущения'!$B$25:$B$30,0),1)) -> 25000 | F43: 0 | G43: 0 | H43: 0 | I43: 0 | J43: =SUM(E43:I43) -> 25000 | L43: Только первый год; проверка NDPA, POPIA и Закона Кении о защите данных.
B44: Проверка защищённости и испытание на проникновение | C44: инфляция | D44: 15000 | E44: =IF($D44="","",$D44*INDEX('A-Допущения'!$C$25:$G$30,MATCH($C44,'A-Допущения'!$B$25:$B$30,0),1)) -> 15000 | F44: =IF($D44="","",$D44*INDEX('A-Допущения'!$C$25:$G$30,MATCH($C44,'A-Допущения'!$B$25:$B$30,0),2)) -> 16200 | G44: =IF($D44="","",$D44*INDEX('A-Допущения'!$C$25:$G$30,MATCH($C44,'A-Допущения'!$B$25:$B$30,0),3)) -> 17496 | H44: =IF($D44="","",$D44*INDEX('A-Допущения'!$C$25:$G$30,MATCH($C44,'A-Допущения'!$B$25:$B$30,0),4)) -> 18895.68 | I44: =IF($D44="","",$D44*INDEX('A-Допущения'!$C$25:$G$30,MATCH($C44,'A-Допущения'!$B$25:$B$30,0),5)) -> 20407.334 | J44: =SUM(E44:I44) -> 87999.014 | L44: Ежегодная проверка; стоимость растёт с инфляцией.
B45: Перенос данных и интеграции при запуске | C45: инфляция | D45: 20000 | E45: =IF($D45="","",$D45*INDEX('A-Допущения'!$C$25:$G$30,MATCH($C45,'A-Допущения'!$B$25:$B$30,0),1)) -> 20000 | F45: 0 | G45: 0 | H45: 0 | I45: 0 | J45: =SUM(E45:I45) -> 20000 | L45: Только первый год.
B46: Обучение команды | C46: ФОТ | D46: 10000 | E46: =IF($D46="","",$D46*INDEX('A-Допущения'!$C$25:$G$30,MATCH($C46,'A-Допущения'!$B$25:$B$30,0),1)) -> 10000 | F46: 0 | G46: 0 | H46: 0 | I46: 0 | J46: =SUM(E46:I46) -> 10000 | L46: Только первый год.
...

Sheet B-Допущения
B2: Допущения модели TCO — Africa Delivery
B3: Заполняются только ячейки с жёлтой заливкой. Все числа ниже — пример, заменить своими.
B5: 1. Драйверы бизнеса — заполнить
B6: Показатель | C6: Год 1 | D6: Год 2 | E6: Год 3 | F6: Год 4 | G6: Год 5 | H6: Комментарий / источник
B7: Активные пользователи (на конец года) | C7: 1000000 | D7: 2000000 | E7: 4000000 | F7: 7000000 | G7: 10000000 | H7: Цель кейса: 1 млн активных пользователей в первый год; расчётный сценарий — 10 млн.
B8: Число заказов в год | C8: 300000 | D8: 1800000 | E8: 6000000 | F8: 12000000 | G8: 18000000 | H8: От 300 тыс. до 18 млн заказов в год; единый сценарий спроса для всех вариантов.
B9: Средний чек (AOV), $ | C9: 25 | D9: 26 | E9: 27 | F9: 28 | G9: 29 | H9: Плановая оценка среднего чека; доллары США 2026 года; точность ±30%.
B10: GMV, $ в год (расчёт) | C10: =C8*C9 -> 7500000 | D10: =D8*D9 -> 46800000 | E10: =E8*E9 -> 162000000 | F10: =F8*F9 -> 336000000 | G10: =G8*G9 -> 522000000 | H10: Расчёт: число заказов за год × средний чек.
B12: 2. Финансовые допущения — заполнить
B13: Параметр | C13: Значение | H13: Комментарий / источник
B14: Инфляция затрат, % в год | C14: 0.08 | H14: Плановое допущение из модели задания 2; применяется к затратам, растущим с инфляцией.
B15: Рост ФОТ, % в год | C15: 0.12 | H15: Плановое допущение из модели задания 2; применяется к фонду оплаты труда.
B16: Ставка дисконтирования, % в год | C16: 0.2 | H16: Ставка дисконтирования для стартапа с высоким уровнем риска.
B17: Резерв на непредвиденное (contingency), % | C17: 0.15 | H17: Резерв начисляется на сумму блоков 1–5.
B18: Бюджет CFO на облако, $/мес | C18: 5000 | H18: Письмо финансового директора, п. 1: жёсткий лимит $5 000 в месяц.
B19: Стоимость минуты простоя, $ | C19: 12000 | H19: Оценка инвестора; используется для анализа чувствительности, а не как подтверждённый ожидаемый ущерб.
B20: Целевой SLO (доступность), % | C20: 0.9995 | H20: Для сопоставимости используется тот же плановый уровень обслуживания, что и в варианте A.
B21: Учитывать стоимость простоя в TCO (1 — да, 0 — нет) | C21: 1 | H21: Значение 1 сохраняет оценку потерь от простоя отдельно от прямых затрат.
B23: 3. Индексы роста — расчёт, не редактировать
B24: Драйвер | C24: Год 1 | D24: Год 2 | E24: Год 3 | F24: Год 4 | G24: Год 5 | H24: Как считается
B25: мощность | C25: =SQRT(C7/$C$7) -> 1 | D25: =SQRT(D7/$C$7) -> 1.4142136 | E25: =SQRT(E7/$C$7) -> 2 | F25: =SQRT(F7/$C$7) -> 2.6457513 | G25: =SQRT(G7/$C$7) -> 3.1622777 | H25: Квадратный корень из роста активных пользователей; учитывает экономию от масштаба инфраструктуры.
B26: нагрузка заказов | C26: =SQRT(C8/$C$8) -> 1 | D26: =SQRT(D8/$C$8) -> 2.4494897 | E26: =SQRT(E8/$C$8) -> 4.472136 | F26: =SQRT(F8/$C$8) -> 6.3245553 | G26: =SQRT(G8/$C$8) -> 7.7459667 | H26: Квадратный корень из роста числа заказов; применяется к трафику и асинхронной обработке.
B27: инфляция | C27: =1 -> 1 | D27: =C27*(1+$C$14) -> 1.08 | E27: =D27*(1+$C$14) -> 1.1664 | F27: =E27*(1+$C$14) -> 1.259712 | G27: =F27*(1+$C$14) -> 1.360489 | H27: Год N = предыдущий год × (1 + инфляция затрат).
B28: ФОТ | C28: =1 -> 1 | D28: =C28*(1+$C$15) -> 1.12 | E28: =D28*(1+$C$15) -> 1.2544 | F28: =E28*(1+$C$15) -> 1.404928 | G28: =F28*(1+$C$15) -> 1.5735194 | H28: Год N = предыдущий год × (1 + рост ФОТ).
B29: заказы | C29: =C8/$C$8 -> 1 | D29: =D8/$C$8 -> 6 | E29: =E8/$C$8 -> 20 | F29: =F8/$C$8 -> 40 | G29: =G8/$C$8 -> 60 | H29: Линейная зависимость от числа заказов для поштучно тарифицируемых услуг партнёров.
B30: оборот (GMV) | C30: =C10/$C$10 -> 1 | D30: =D10/$C$10 -> 6.24 | E30: =E10/$C$10 -> 21.6 | F30: =F10/$C$10 -> 44.8 | G30: =G10/$C$10 -> 69.6 | H30: Линейная зависимость комиссий платёжных провайдеров от оборота.
B32: Заданные показатели мощности растут пропорционально квадратному корню из нагрузки и учитывают экономию от масштаба; транзакционные расходы растут линейно с числом заказов или оборотом.

Sheet B-TCO
B2: TCO на 5 лет — Africa Delivery
B3: Заполняем колонки «Драйвер роста» и «База, $/год (Год 1)». Годы 1–5 считаются автоматически.
B5: Статья затрат | C5: Драйвер роста | D5: База, $/год (Год 1) | E5: Год 1 | F5: Год 2 | G5: Год 3 | H5: Год 4 | I5: Год 5 | J5: Итого 5 лет | K5: Доля | L5: Комментарий / источник
B6: БЛОК 1. Облачная инфраструктура (OpEx)
B7: Вычислительные ресурсы и оркестрация | C7: мощность | D7: 24000 | E7: =IF($D7="","",$D7*INDEX('B-Допущения'!$C$25:$G$30,MATCH($C7,'B-Допущения'!$B$25:$B$30,0),1)) -> 24000 | F7: =IF($D7="","",$D7*INDEX('B-Допущения'!$C$25:$G$30,MATCH($C7,'B-Допущения'!$B$25:$B$30,0),2)) -> 33941.125 | G7: =IF($D7="","",$D7*INDEX('B-Допущения'!$C$25:$G$30,MATCH($C7,'B-Допущения'!$B$25:$B$30,0),3)) -> 48000 | H7: =IF($D7="","",$D7*INDEX('B-Допущения'!$C$25:$G$30,MATCH($C7,'B-Допущения'!$B$25:$B$30,0),4)) -> 63498.031 | I7: =IF($D7="","",$D7*INDEX('B-Допущения'!$C$25:$G$30,MATCH($C7,'B-Допущения'!$B$25:$B$30,0),5)) -> 75894.664 | J7: =SUM(E7:I7) -> 245333.82 | L7: 6–8 укрупнённых сервисов и управляемая оркестрация.
B8: Управляемая СУБД PostgreSQL | C8: мощность | D8: 15000 | E8: =IF($D8="","",$D8*INDEX('B-Допущения'!$C$25:$G$30,MATCH($C8,'B-Допущения'!$B$25:$B$30,0),1)) -> 15000 | F8: =IF($D8="","",$D8*INDEX('B-Допущения'!$C$25:$G$30,MATCH($C8,'B-Допущения'!$B$25:$B$30,0),2)) -> 21213.203 | G8: =IF($D8="","",$D8*INDEX('B-Допущения'!$C$25:$G$30,MATCH($C8,'B-Допущения'!$B$25:$B$30,0),3)) -> 30000 | H8: =IF($D8="","",$D8*INDEX('B-Допущения'!$C$25:$G$30,MATCH($C8,'B-Допущения'!$B$25:$B$30,0),4)) -> 39686.27 | I8: =IF($D8="","",$D8*INDEX('B-Допущения'!$C$25:$G$30,MATCH($C8,'B-Допущения'!$B$25:$B$30,0),5)) -> 47434.165 | J8: =SUM(E8:I8) -> 153333.64 | L8: Несколько схем или экземпляров для сервисов; предварительная оценка.
B9: Объектное хранилище и резервные копии | C9: мощность | D9: 4000 | E9: =IF($D9="","",$D9*INDEX('B-Допущения'!$C$25:$G$30,MATCH($C9,'B-Допущения'!$B$25:$B$30,0),1)) -> 4000 | F9: =IF($D9="","",$D9*INDEX('B-Допущения'!$C$25:$G$30,MATCH($C9,'B-Допущения'!$B$25:$B$30,0),2)) -> 5656.8542 | G9: =IF($D9="","",$D9*INDEX('B-Допущения'!$C$25:$G$30,MATCH($C9,'B-Допущения'!$B$25:$B$30,0),3)) -> 8000 | H9: =IF($D9="","",$D9*INDEX('B-Допущения'!$C$25:$G$30,MATCH($C9,'B-Допущения'!$B$25:$B$30,0),4)) -> 10583.005 | I9: =IF($D9="","",$D9*INDEX('B-Допущения'!$C$25:$G$30,MATCH($C9,'B-Допущения'!$B$25:$B$30,0),5)) -> 12649.111 | J9: =SUM(E9:I9) -> 40888.97 | L9: Повышенные накладные расходы на сервисы и данные.
B10: Сеть доставки содержимого (CDN) и исходящий трафик | C10: нагрузка заказов | D10: 8000 | E10: =IF($D10="","",$D10*INDEX('B-Допущения'!$C$25:$G$30,MATCH($C10,'B-Допущения'!$B$25:$B$30,0),1)) -> 8000 | F10: =IF($D10="","",$D10*INDEX('B-Допущения'!$C$25:$G$30,MATCH($C10,'B-Допущения'!$B$25:$B$30,0),2)) -> 19595.918 | G10: =IF($D10="","",$D10*INDEX('B-Допущения'!$C$25:$G$30,MATCH($C10,'B-Допущения'!$B$25:$B$30,0),3)) -> 35777.088 | H10: =IF($D10="","",$D10*INDEX('B-Допущения'!$C$25:$G$30,MATCH($C10,'B-Допущения'!$B$25:$B$30,0),4)) -> 50596.443 | I10: =IF($D10="","",$D10*INDEX('B-Допущения'!$C$25:$G$30,MATCH($C10,'B-Допущения'!$B$25:$B$30,0),5)) -> 61967.734 | J10: =SUM(E10:I10) -> 175937.18 | L10: Мобильные изображения и исходящий трафик программных интерфейсов.
B11: Управляемый обмен сообщениями | C11: нагрузка заказов | D11: 5000 | E11: =IF($D11="","",$D11*INDEX('B-Допущения'!$C$25:$G$30,MATCH($C11,'B-Допущения'!$B$25:$B$30,0),1)) -> 5000 | F11: =IF($D11="","",$D11*INDEX('B-Допущения'!$C$25:$G$30,MATCH($C11,'B-Допущения'!$B$25:$B$30,0),2)) -> 12247.449 | G11: =IF($D11="","",$D11*INDEX('B-Допущения'!$C$25:$G$30,MATCH($C11,'B-Допущения'!$B$25:$B$30,0),3)) -> 22360.68 | H11: =IF($D11="","",$D11*INDEX('B-Допущения'!$C$25:$G$30,MATCH($C11,'B-Допущения'!$B$25:$B$30,0),4)) -> 31622.777 | I11: =IF($D11="","",$D11*INDEX('B-Допущения'!$C$25:$G$30,MATCH($C11,'B-Допущения'!$B$25:$B$30,0),5)) -> 38729.833 | J11: =SUM(E11:I11) -> 109960.74 | L11: Событийный обмен и взаимодействие между сервисами.
B12: Тёплый резерв для аварийного восстановления | C12: мощность | D12: 12000 | E12: =IF($D12="","",$D12*INDEX('B-Допущения'!$C$25:$G$30,MATCH($C12,'B-Допущения'!$B$25:$B$30,0),1)) -> 12000 | F12: =IF($D12="","",$D12*INDEX('B-Допущения'!$C$25:$G$30,MATCH($C12,'B-Допущения'!$B$25:$B$30,0),2)) -> 16970.563 | G12: =IF($D12="","",$D12*INDEX('B-Допущения'!$C$25:$G$30,MATCH($C12,'B-Допущения'!$B$25:$B$30,0),3)) -> 24000 | H12: =IF($D12="","",$D12*INDEX('B-Допущения'!$C$25:$G$30,MATCH($C12,'B-Допущения'!$B$25:$B$30,0),4)) -> 31749.016 | I12: =IF($D12="","",$D12*INDEX('B-Допущения'!$C$25:$G$30,MATCH($C12,'B-Допущения'!$B$25:$B$30,0),5)) -> 37947.332 | J12: =SUM(E12:I12) -> 122666.91 | L12: Дополнительные развёртываемые компоненты и хранилища данных.
B13: Локальное размещение данных в Нигерии | C13: инфляция | D13: 12000 | E13: =IF($D13="","",$D13*INDEX('B-Допущения'!$C$25:$G$30,MATCH($C13,'B-Допущения'!$B$25:$B$30,0),1)) -> 12000 | F13: =IF($D13="","",$D13*INDEX('B-Допущения'!$C$25:$G$30,MATCH($C13,'B-Допущения'!$B$25:$B$30,0),2)) -> 12960 | G13: =IF($D13="","",$D13*INDEX('B-Допущения'!$C$25:$G$30,MATCH($C13,'B-Допущения'!$B$25:$B$30,0),3)) -> 13996.8 | H13: =IF($D13="","",$D13*INDEX('B-Допущения'!$C$25:$G$30,MATCH($C13,'B-Допущения'!$B$25:$B$30,0),4)) -> 15116.544 | I13: =IF($D13="","",$D13*INDEX('B-Допущения'!$C$25:$G$30,MATCH($C13,'B-Допущения'!$B$25:$B$30,0),5)) -> 16325.868 | J13: =SUM(E13:I13) -> 70399.212 | L13: Плановый резерв; требуется коммерческое предложение провайдера из задания 4.
C14: инфляция | E14: =IF($D14="","",$D14*INDEX('B-Допущения'!$C$25:$G$30,MATCH($C14,'B-Допущения'!$B$25:$B$30,0),1)) | F14: =IF($D14="","",$D14*INDEX('B-Допущения'!$C$25:$G$30,MATCH($C14,'B-Допущения'!$B$25:$B$30,0),2)) | G14: =IF($D14="","",$D14*INDEX('B-Допущения'!$C$25:$G$30,MATCH($C14,'B-Допущения'!$B$25:$B$30,0),3)) | H14: =IF($D14="","",$D14*INDEX('B-Допущения'!$C$25:$G$30,MATCH($C14,'B-Допущения'!$B$25:$B$30,0),4)) | I14: =IF($D14="","",$D14*INDEX('B-Допущения'!$C$25:$G$30,MATCH($C14,'B-Допущения'!$B$25:$B$30,0),5)) | J14: =SUM(E14:I14) -> 0
B15: Итого по блоку | E15: =SUM(E7:E14) -> 80000 | F15: =SUM(F7:F14) -> 122585.11 | G15: =SUM(G7:G14) -> 182134.57 | H15: =SUM(H7:H14) -> 242852.09 | I15: =SUM(I7:I14) -> 290948.71 | J15: =SUM(E15:I15) -> 918520.47 | K15: =IFERROR(J15/$J$51,0) -> 0.020456333
B17: БЛОК 2. Лицензии, SaaS и инструменты
B18: Наблюдаемость | C18: мощность | D18: 6000 | E18: =IF($D18="","",$D18*INDEX('B-Допущения'!$C$25:$G$30,MATCH($C18,'B-Допущения'!$B$25:$B$30,0),1)) -> 6000 | F18: =IF($D18="","",$D18*INDEX('B-Допущения'!$C$25:$G$30,MATCH($C18,'B-Допущения'!$B$25:$B$30,0),2)) -> 8485.2814 | G18: =IF($D18="","",$D18*INDEX('B-Допущения'!$C$25:$G$30,MATCH($C18,'B-Допущения'!$B$25:$B$30,0),3)) -> 12000 | H18: =IF($D18="","",$D18*INDEX('B-Допущения'!$C$25:$G$30,MATCH($C18,'B-Допущения'!$B$25:$B$30,0),4)) -> 15874.508 | I18: =IF($D18="","",$D18*INDEX('B-Допущения'!$C$25:$G$30,MATCH($C18,'B-Допущения'!$B$25:$B$30,0),5)) -> 18973.666 | J18: =SUM(E18:I18) -> 61333.455 | L18: Журналы, метрики и трассировка распределённой системы.
B19: Непрерывная интеграция и доставка, репозиторий, артефакты | C19: инфляция | D19: 2400 | E19: =IF($D19="","",$D19*INDEX('B-Допущения'!$C$25:$G$30,MATCH($C19,'B-Допущения'!$B$25:$B$30,0),1)) -> 2400 | F19: =IF($D19="","",$D19*INDEX('B-Допущения'!$C$25:$G$30,MATCH($C19,'B-Допущения'!$B$25:$B$30,0),2)) -> 2592 | G19: =IF($D19="","",$D19*INDEX('B-Допущения'!$C$25:$G$30,MATCH($C19,'B-Допущения'!$B$25:$B$30,0),3)) -> 2799.36 | H19: =IF($D19="","",$D19*INDEX('B-Допущения'!$C$25:$G$30,MATCH($C19,'B-Допущения'!$B$25:$B$30,0),4)) -> 3023.3088 | I19: =IF($D19="","",$D19*INDEX('B-Допущения'!$C$25:$G$30,MATCH($C19,'B-Допущения'!$B$25:$B$30,0),5)) -> 3265.1735 | J19: =SUM(E19:I19) -> 14079.842 | L19: Несколько независимо развёртываемых компонентов.
B20: Безопасность: межсетевой экран веб-приложений и секреты | C20: мощность | D20: 6000 | E20: =IF($D20="","",$D20*INDEX('B-Допущения'!$C$25:$G$30,MATCH($C20,'B-Допущения'!$B$25:$B$30,0),1)) -> 6000 | F20: =IF($D20="","",$D20*INDEX('B-Допущения'!$C$25:$G$30,MATCH($C20,'B-Допущения'!$B$25:$B$30,0),2)) -> 8485.2814 | G20: =IF($D20="","",$D20*INDEX('B-Допущения'!$C$25:$G$30,MATCH($C20,'B-Допущения'!$B$25:$B$30,0),3)) -> 12000 | H20: =IF($D20="","",$D20*INDEX('B-Допущения'!$C$25:$G$30,MATCH($C20,'B-Допущения'!$B$25:$B$30,0),4)) -> 15874.508 | I20: =IF($D20="","",$D20*INDEX('B-Допущения'!$C$25:$G$30,MATCH($C20,'B-Допущения'!$B$25:$B$30,0),5)) -> 18973.666 | J20: =SUM(E20:I20) -> 61333.455 | L20: Больше технических учётных записей и границ доступа.
B21: Фиксированная плата за WhatsApp Business API | C21: инфляция | D21: 1200 | E21: =IF($D21="","",$D21*INDEX('B-Допущения'!$C$25:$G$30,MATCH($C21,'B-Допущения'!$B$25:$B$30,0),1)) -> 1200 | F21: =IF($D21="","",$D21*INDEX('B-Допущения'!$C$25:$G$30,MATCH($C21,'B-Допущения'!$B$25:$B$30,0),2)) -> 1296 | G21: =IF($D21="","",$D21*INDEX('B-Допущения'!$C$25:$G$30,MATCH($C21,'B-Допущения'!$B$25:$B$30,0),3)) -> 1399.68 | H21: =IF($D21="","",$D21*INDEX('B-Допущения'!$C$25:$G$30,MATCH($C21,'B-Допущения'!$B$25:$B$30,0),4)) -> 1511.6544 | I21: =IF($D21="","",$D21*INDEX('B-Допущения'!$C$25:$G$30,MATCH($C21,'B-Допущения'!$B$25:$B$30,0),5)) -> 1632.5868 | J21: =SUM(E21:I21) -> 7039.9212 | L21: Постоянная плата; переменные расходы учтены в блоке 3.
B22: Прочие инструменты разработки | C22: инфляция | D22: 2400 | E22: =IF($D22="","",$D22*INDEX('B-Допущения'!$C$25:$G$30,MATCH($C22,'B-Допущения'!$B$25:$B$30,0),1)) -> 2400 | F22: =IF($D22="","",$D22*INDEX('B-Допущения'!$C$25:$G$30,MATCH($C22,'B-Допущения'!$B$25:$B$30,0),2)) -> 2592 | G22: =IF($D22="","",$D22*INDEX('B-Допущения'!$C$25:$G$30,MATCH($C22,'B-Допущения'!$B$25:$B$30,0),3)) -> 2799.36 | H22: =IF($D22="","",$D22*INDEX('B-Допущения'!$C$25:$G$30,MATCH($C22,'B-Допущения'!$B$25:$B$30,0),4)) -> 3023.3088 | I22: =IF($D22="","",$D22*INDEX('B-Допущения'!$C$25:$G$30,MATCH($C22,'B-Допущения'!$B$25:$B$30,0),5)) -> 3265.1735 | J22: =SUM(E22:I22) -> 14079.842 | L22: Инструменты для расширенной команды и нескольких сервисов.
C23: инфляция | E23: =IF($D23="","",$D23*INDEX('B-Допущения'!$C$25:$G$30,MATCH($C23,'B-Допущения'!$B$25:$B$30,0),1)) | F23: =IF($D23="","",$D23*INDEX('B-Допущения'!$C$25:$G$30,MATCH($C23,'B-Допущения'!$B$25:$B$30,0),2)) | G23: =IF($D23="","",$D23*INDEX('B-Допущения'!$C$25:$G$30,MATCH($C23,'B-Допущения'!$B$25:$B$30,0),3)) | H23: =IF($D23="","",$D23*INDEX('B-Допущения'!$C$25:$G$30,MATCH($C23,'B-Допущения'!$B$25:$B$30,0),4)) | I23: =IF($D23="","",$D23*INDEX('B-Допущения'!$C$25:$G$30,MATCH($C23,'B-Допущения'!$B$25:$B$30,0),5)) | J23: =SUM(E23:I23) -> 0
B24: Итого по блоку | E24: =SUM(E18:E23) -> 18000 | F24: =SUM(F18:F23) -> 23450.563 | G24: =SUM(G18:G23) -> 30998.4 | H24: =SUM(H18:H23) -> 39307.288 | I24: =SUM(I18:I23) -> 46110.266 | J24: =SUM(E24:I24) -> 157866.52 | K24: =IFERROR(J24/$J$51,0) -> 0.003515839
B26: БЛОК 3. Транзакционные расходы (Buy / Partner)
B27: Комиссии платёжных провайдеров | C27: оборот (GMV) | D27: 187500 | E27: =IF($D27="","",$D27*INDEX('B-Допущения'!$C$25:$G$30,MATCH($C27,'B-Допущения'!$B$25:$B$30,0),1)) -> 187500 | F27: =IF($D27="","",$D27*INDEX('B-Допущения'!$C$25:$G$30,MATCH($C27,'B-Допущения'!$B$25:$B$30,0),2)) -> 1170000 | G27: =IF($D27="","",$D27*INDEX('B-Допущения'!$C$25:$G$30,MATCH($C27,'B-Допущения'!$B$25:$B$30,0),3)) -> 4050000 | H27: =IF($D27="","",$D27*INDEX('B-Допущения'!$C$25:$G$30,MATCH($C27,'B-Допущения'!$B$25:$B$30,0),4)) -> 8400000 | I27: =IF($D27="","",$D27*INDEX('B-Допущения'!$C$25:$G$30,MATCH($C27,'B-Допущения'!$B$25:$B$30,0),5)) -> 13050000 | J27: =SUM(E27:I27) -> 26857500 | L27: 2,5% оборота первого года; письмо финансового директора, п. 6.
B28: SMS-уведомления | C28: заказы | D28: 12000 | E28: =IF($D28="","",$D28*INDEX('B-Допущения'!$C$25:$G$30,MATCH($C28,'B-Допущения'!$B$25:$B$30,0),1)) -> 12000 | F28: =IF($D28="","",$D28*INDEX('B-Допущения'!$C$25:$G$30,MATCH($C28,'B-Допущения'!$B$25:$B$30,0),2)) -> 72000 | G28: =IF($D28="","",$D28*INDEX('B-Допущения'!$C$25:$G$30,MATCH($C28,'B-Допущения'!$B$25:$B$30,0),3)) -> 240000 | H28: =IF($D28="","",$D28*INDEX('B-Допущения'!$C$25:$G$30,MATCH($C28,'B-Допущения'!$B$25:$B$30,0),4)) -> 480000 | I28: =IF($D28="","",$D28*INDEX('B-Допущения'!$C$25:$G$30,MATCH($C28,'B-Допущения'!$B$25:$B$30,0),5)) -> 720000 | J28: =SUM(E28:I28) -> 1524000 | L28: $0,04 на заказ; допущение модели задания 2.
B29: Сообщения WhatsApp | C29: заказы | D29: 9000 | E29: =IF($D29="","",$D29*INDEX('B-Допущения'!$C$25:$G$30,MATCH($C29,'B-Допущения'!$B$25:$B$30,0),1)) -> 9000 | F29: =IF($D29="","",$D29*INDEX('B-Допущения'!$C$25:$G$30,MATCH($C29,'B-Допущения'!$B$25:$B$30,0),2)) -> 54000 | G29: =IF($D29="","",$D29*INDEX('B-Допущения'!$C$25:$G$30,MATCH($C29,'B-Допущения'!$B$25:$B$30,0),3)) -> 180000 | H29: =IF($D29="","",$D29*INDEX('B-Допущения'!$C$25:$G$30,MATCH($C29,'B-Допущения'!$B$25:$B$30,0),4)) -> 360000 | I29: =IF($D29="","",$D29*INDEX('B-Допущения'!$C$25:$G$30,MATCH($C29,'B-Допущения'!$B$25:$B$30,0),5)) -> 540000 | J29: =SUM(E29:I29) -> 1143000 | L29: $0,03 на заказ; допущение модели задания 2.
B30: Комиссии за интеграцию с логистическими партнёрами | C30: заказы | D30: 30000 | E30: =IF($D30="","",$D30*INDEX('B-Допущения'!$C$25:$G$30,MATCH($C30,'B-Допущения'!$B$25:$B$30,0),1)) -> 30000 | F30: =IF($D30="","",$D30*INDEX('B-Допущения'!$C$25:$G$30,MATCH($C30,'B-Допущения'!$B$25:$B$30,0),2)) -> 180000 | G30: =IF($D30="","",$D30*INDEX('B-Допущения'!$C$25:$G$30,MATCH($C30,'B-Допущения'!$B$25:$B$30,0),3)) -> 600000 | H30: =IF($D30="","",$D30*INDEX('B-Допущения'!$C$25:$G$30,MATCH($C30,'B-Допущения'!$B$25:$B$30,0),4)) -> 1200000 | I30: =IF($D30="","",$D30*INDEX('B-Допущения'!$C$25:$G$30,MATCH($C30,'B-Допущения'!$B$25:$B$30,0),5)) -> 1800000 | J30: =SUM(E30:I30) -> 3810000 | L30: $0,10 на заказ; стоимость курьерской доставки не включена.
C31: инфляция | E31: =IF($D31="","",$D31*INDEX('B-Допущения'!$C$25:$G$30,MATCH($C31,'B-Допущения'!$B$25:$B$30,0),1)) | F31: =IF($D31="","",$D31*INDEX('B-Допущения'!$C$25:$G$30,MATCH($C31,'B-Допущения'!$B$25:$B$30,0),2)) | G31: =IF($D31="","",$D31*INDEX('B-Допущения'!$C$25:$G$30,MATCH($C31,'B-Допущения'!$B$25:$B$30,0),3)) | H31: =IF($D31="","",$D31*INDEX('B-Допущения'!$C$25:$G$30,MATCH($C31,'B-Допущения'!$B$25:$B$30,0),4)) | I31: =IF($D31="","",$D31*INDEX('B-Допущения'!$C$25:$G$30,MATCH($C31,'B-Допущения'!$B$25:$B$30,0),5)) | J31: =SUM(E31:I31) -> 0
B32: Итого по блоку | E32: =SUM(E27:E31) -> 238500 | F32: =SUM(F27:F31) -> 1476000 | G32: =SUM(G27:G31) -> 5070000 | H32: =SUM(H27:H31) -> 10440000 | I32: =SUM(I27:I31) -> 16110000 | J32: =SUM(E32:I32) -> 33334500 | K32: =IFERROR(J32/$J$51,0) -> 0.74239133
B34: БЛОК 4. Команда (ФОТ)
B35: Разработка (6 специалистов) | C35: ФОТ | D35: 360000 | E35: =IF($D35="","",$D35*INDEX('B-Допущения'!$C$25:$G$30,MATCH($C35,'B-Допущения'!$B$25:$B$30,0),1)) -> 360000 | F35: =IF($D35="","",$D35*INDEX('B-Допущения'!$C$25:$G$30,MATCH($C35,'B-Допущения'!$B$25:$B$30,0),2)) -> 403200 | G35: =IF($D35="","",$D35*INDEX('B-Допущения'!$C$25:$G$30,MATCH($C35,'B-Допущения'!$B$25:$B$30,0),3)) -> 451584 | H35: =IF($D35="","",$D35*INDEX('B-Допущения'!$C$25:$G$30,MATCH($C35,'B-Допущения'!$B$25:$B$30,0),4)) -> 505774.08 | I35: =IF($D35="","",$D35*INDEX('B-Допущения'!$C$25:$G$30,MATCH($C35,'B-Допущения'!$B$25:$B$30,0),5)) -> 566466.97 | J35: =SUM(E35:I35) -> 2287025 | L35: 6 × $60 тыс. полной годовой стоимости специалиста.
B36: Эксплуатация и надёжность (2 специалиста) | C36: ФОТ | D36: 120000 | E36: =IF($D36="","",$D36*INDEX('B-Допущения'!$C$25:$G$30,MATCH($C36,'B-Допущения'!$B$25:$B$30,0),1)) -> 120000 | F36: =IF($D36="","",$D36*INDEX('B-Допущения'!$C$25:$G$30,MATCH($C36,'B-Допущения'!$B$25:$B$30,0),2)) -> 134400 | G36: =IF($D36="","",$D36*INDEX('B-Допущения'!$C$25:$G$30,MATCH($C36,'B-Допущения'!$B$25:$B$30,0),3)) -> 150528 | H36: =IF($D36="","",$D36*INDEX('B-Допущения'!$C$25:$G$30,MATCH($C36,'B-Допущения'!$B$25:$B$30,0),4)) -> 168591.36 | I36: =IF($D36="","",$D36*INDEX('B-Допущения'!$C$25:$G$30,MATCH($C36,'B-Допущения'!$B$25:$B$30,0),5)) -> 188822.32 | J36: =SUM(E36:I36) -> 762341.68 | L36: 2 × $60 тыс. полной годовой стоимости специалиста.
B37: Поддержка и дежурство | C37: ФОТ | D37: 96000 | E37: =IF($D37="","",$D37*INDEX('B-Допущения'!$C$25:$G$30,MATCH($C37,'B-Допущения'!$B$25:$B$30,0),1)) -> 96000 | F37: =IF($D37="","",$D37*INDEX('B-Допущения'!$C$25:$G$30,MATCH($C37,'B-Допущения'!$B$25:$B$30,0),2)) -> 107520 | G37: =IF($D37="","",$D37*INDEX('B-Допущения'!$C$25:$G$30,MATCH($C37,'B-Допущения'!$B$25:$B$30,0),3)) -> 120422.4 | H37: =IF($D37="","",$D37*INDEX('B-Допущения'!$C$25:$G$30,MATCH($C37,'B-Допущения'!$B$25:$B$30,0),4)) -> 134873.09 | I37: =IF($D37="","",$D37*INDEX('B-Допущения'!$C$25:$G$30,MATCH($C37,'B-Допущения'!$B$25:$B$30,0),5)) -> 151057.86 | J37: =SUM(E37:I37) -> 609873.35 | L37: Расширенная поддержка распределённой системы.
B38: Архитектура и управление | C38: ФОТ | D38: 120000 | E38: =IF($D38="","",$D38*INDEX('B-Допущения'!$C$25:$G$30,MATCH($C38,'B-Допущения'!$B$25:$B$30,0),1)) -> 120000 | F38: =IF($D38="","",$D38*INDEX('B-Допущения'!$C$25:$G$30,MATCH($C38,'B-Допущения'!$B$25:$B$30,0),2)) -> 134400 | G38: =IF($D38="","",$D38*INDEX('B-Допущения'!$C$25:$G$30,MATCH($C38,'B-Допущения'!$B$25:$B$30,0),3)) -> 150528 | H38: =IF($D38="","",$D38*INDEX('B-Допущения'!$C$25:$G$30,MATCH($C38,'B-Допущения'!$B$25:$B$30,0),4)) -> 168591.36 | I38: =IF($D38="","",$D38*INDEX('B-Допущения'!$C$25:$G$30,MATCH($C38,'B-Допущения'!$B$25:$B$30,0),5)) -> 188822.32 | J38: =SUM(E38:I38) -> 762341.68 | L38: Координация архитектуры, продукта и команды.
C39: инфляция | E39: =IF($D39="","",$D39*INDEX('B-Допущения'!$C$25:$G$30,MATCH($C39,'B-Допущения'!$B$25:$B$30,0),1)) | F39: =IF($D39="","",$D39*INDEX('B-Допущения'!$C$25:$G$30,MATCH($C39,'B-Допущения'!$B$25:$B$30,0),2)) | G39: =IF($D39="","",$D39*INDEX('B-Допущения'!$C$25:$G$30,MATCH($C39,'B-Допущения'!$B$25:$B$30,0),3)) | H39: =IF($D39="","",$D39*INDEX('B-Допущения'!$C$25:$G$30,MATCH($C39,'B-Допущения'!$B$25:$B$30,0),4)) | I39: =IF($D39="","",$D39*INDEX('B-Допущения'!$C$25:$G$30,MATCH($C39,'B-Допущения'!$B$25:$B$30,0),5)) | J39: =SUM(E39:I39) -> 0
B40: Итого по блоку | E40: =SUM(E35:E39) -> 696000 | F40: =SUM(F35:F39) -> 779520 | G40: =SUM(G35:G39) -> 873062.4 | H40: =SUM(H35:H39) -> 977829.89 | I40: =SUM(I35:I39) -> 1095169.5 | J40: =SUM(E40:I40) -> 4421581.8 | K40: =IFERROR(J40/$J$51,0) -> 0.098472873
B42: БЛОК 5. Разовые затраты и комплаенс
B43: Юридический аудит и проверка соответствия требованиям | C43: инфляция | D43: 25000 | E43: =IF($D43="","",$D43*INDEX('B-Допущения'!$C$25:$G$30,MATCH($C43,'B-Допущения'!$B$25:$B$30,0),1)) -> 25000 | F43: 0 | G43: 0 | H43: 0 | I43: 0 | J43: =SUM(E43:I43) -> 25000 | L43: Только первый год; проверка NDPA, POPIA и Закона Кении о защите данных.
B44: Проверка защищённости и испытание на проникновение | C44: инфляция | D44: 20000 | E44: =IF($D44="","",$D44*INDEX('B-Допущения'!$C$25:$G$30,MATCH($C44,'B-Допущения'!$B$25:$B$30,0),1)) -> 20000 | F44: =IF($D44="","",$D44*INDEX('B-Допущения'!$C$25:$G$30,MATCH($C44,'B-Допущения'!$B$25:$B$30,0),2)) -> 21600 | G44: =IF($D44="","",$D44*INDEX('B-Допущения'!$C$25:$G$30,MATCH($C44,'B-Допущения'!$B$25:$B$30,0),3)) -> 23328 | H44: =IF($D44="","",$D44*INDEX('B-Допущения'!$C$25:$G$30,MATCH($C44,'B-Допущения'!$B$25:$B$30,0),4)) -> 25194.24 | I44: =IF($D44="","",$D44*INDEX('B-Допущения'!$C$25:$G$30,MATCH($C44,'B-Допущения'!$B$25:$B$30,0),5)) -> 27209.779 | J44: =SUM(E44:I44) -> 117332.02 | L44: Ежегодная проверка распределённой системы.
B45: Перенос данных и интеграции при запуске | C45: инфляция | D45: 40000 | E45: =IF($D45="","",$D45*INDEX('B-Допущения'!$C$25:$G$30,MATCH($C45,'B-Допущения'!$B$25:$B$30,0),1)) -> 40000 | F45: 0 | G45: 0 | H45: 0 | I45: 0 | J45: =SUM(E45:I45) -> 40000 | L45: Только первый год.
B46: Обучение команды | C46: ФОТ | D46: 30000 | E46: =IF($D46="","",$D46*INDEX('B-Допущения'!$C$25:$G$30,MATCH($C46,'B-Допущения'!$B$25:$B$30,0),1)) -> 30000 | F46: 0 | G46: 0 | H46: 0 | I46: 0 | J46: =SUM(E46:I46) -> 30000 | L46: Только первый год.
...

Sheet C-Допущения
B2: Допущения модели TCO — Africa Delivery
B3: Заполняются только ячейки с жёлтой заливкой. Все числа ниже — пример, заменить своими.
B5: 1. Драйверы бизнеса — заполнить
B6: Показатель | C6: Год 1 | D6: Год 2 | E6: Год 3 | F6: Год 4 | G6: Год 5 | H6: Комментарий / источник
B7: Активные пользователи (на конец года) | C7: 1000000 | D7: 2000000 | E7: 4000000 | F7: 7000000 | G7: 10000000 | H7: Цель кейса: 1 млн активных пользователей в первый год; расчётный сценарий — 10 млн.
B8: Число заказов в год | C8: 300000 | D8: 1800000 | E8: 6000000 | F8: 12000000 | G8: 18000000 | H8: От 300 тыс. до 18 млн заказов в год; единый сценарий спроса для всех вариантов.
B9: Средний чек (AOV), $ | C9: 25 | D9: 26 | E9: 27 | F9: 28 | G9: 29 | H9: Плановая оценка среднего чека; доллары США 2026 года; точность ±30%.
B10: GMV, $ в год (расчёт) | C10: =C8*C9 -> 7500000 | D10: =D8*D9 -> 46800000 | E10: =E8*E9 -> 162000000 | F10: =F8*F9 -> 336000000 | G10: =G8*G9 -> 522000000 | H10: Расчёт: число заказов за год × средний чек.
B12: 2. Финансовые допущения — заполнить
B13: Параметр | C13: Значение | H13: Комментарий / источник
B14: Инфляция затрат, % в год | C14: 0.08 | H14: Плановое допущение из модели задания 2; применяется к затратам, растущим с инфляцией.
B15: Рост ФОТ, % в год | C15: 0.12 | H15: Плановое допущение из модели задания 2; применяется к фонду оплаты труда.
B16: Ставка дисконтирования, % в год | C16: 0.2 | H16: Ставка дисконтирования для стартапа с высоким уровнем риска.
B17: Резерв на непредвиденное (contingency), % | C17: 0.15 | H17: Резерв начисляется на сумму блоков 1–5.
B18: Бюджет CFO на облако, $/мес | C18: 5000 | H18: Письмо финансового директора, п. 1: жёсткий лимит $5 000 в месяц.
B19: Стоимость минуты простоя, $ | C19: 12000 | H19: Оценка инвестора; используется для анализа чувствительности, а не как подтверждённый ожидаемый ущерб.
B20: Целевой SLO (доступность), % | C20: 0.9999 | H20: Целевой показатель технического директора — 99,99%; используется для оценки потерь от простоя, а не как подтверждённый сквозной уровень обслуживания.
B21: Учитывать стоимость простоя в TCO (1 — да, 0 — нет) | C21: 1 | H21: Значение 1 сохраняет оценку потерь от простоя отдельно от прямых затрат.
B23: 3. Индексы роста — расчёт, не редактировать
B24: Драйвер | C24: Год 1 | D24: Год 2 | E24: Год 3 | F24: Год 4 | G24: Год 5 | H24: Как считается
B25: мощность | C25: =SQRT(C7/$C$7) -> 1 | D25: =SQRT(D7/$C$7) -> 1.4142136 | E25: =SQRT(E7/$C$7) -> 2 | F25: =SQRT(F7/$C$7) -> 2.6457513 | G25: =SQRT(G7/$C$7) -> 3.1622777 | H25: Квадратный корень из роста активных пользователей; учитывает экономию от масштаба инфраструктуры.
B26: нагрузка заказов | C26: =SQRT(C8/$C$8) -> 1 | D26: =SQRT(D8/$C$8) -> 2.4494897 | E26: =SQRT(E8/$C$8) -> 4.472136 | F26: =SQRT(F8/$C$8) -> 6.3245553 | G26: =SQRT(G8/$C$8) -> 7.7459667 | H26: Квадратный корень из роста числа заказов; применяется к трафику и асинхронной обработке.
B27: инфляция | C27: =1 -> 1 | D27: =C27*(1+$C$14) -> 1.08 | E27: =D27*(1+$C$14) -> 1.1664 | F27: =E27*(1+$C$14) -> 1.259712 | G27: =F27*(1+$C$14) -> 1.360489 | H27: Год N = предыдущий год × (1 + инфляция затрат).
B28: ФОТ | C28: =1 -> 1 | D28: =C28*(1+$C$15) -> 1.12 | E28: =D28*(1+$C$15) -> 1.2544 | F28: =E28*(1+$C$15) -> 1.404928 | G28: =F28*(1+$C$15) -> 1.5735194 | H28: Год N = предыдущий год × (1 + рост ФОТ).
B29: заказы | C29: =C8/$C$8 -> 1 | D29: =D8/$C$8 -> 6 | E29: =E8/$C$8 -> 20 | F29: =F8/$C$8 -> 40 | G29: =G8/$C$8 -> 60 | H29: Линейная зависимость от числа заказов для поштучно тарифицируемых услуг партнёров.
B30: оборот (GMV) | C30: =C10/$C$10 -> 1 | D30: =D10/$C$10 -> 6.24 | E30: =E10/$C$10 -> 21.6 | F30: =F10/$C$10 -> 44.8 | G30: =G10/$C$10 -> 69.6 | H30: Линейная зависимость комиссий платёжных провайдеров от оборота.
B32: Заданные показатели мощности растут пропорционально квадратному корню из нагрузки и учитывают экономию от масштаба; транзакционные расходы растут линейно с числом заказов или оборотом.

Sheet C-TCO
B2: TCO на 5 лет — Africa Delivery
B3: Заполняем колонки «Драйвер роста» и «База, $/год (Год 1)». Годы 1–5 считаются автоматически.
B5: Статья затрат | C5: Драйвер роста | D5: База, $/год (Год 1) | E5: Год 1 | F5: Год 2 | G5: Год 3 | H5: Год 4 | I5: Год 5 | J5: Итого 5 лет | K5: Доля | L5: Комментарий / источник
B6: БЛОК 1. Облачная инфраструктура (OpEx)
B7: Рабочие узлы Kubernetes | C7: мощность | D7: 120000 | E7: =IF($D7="","",$D7*INDEX('C-Допущения'!$C$25:$G$30,MATCH($C7,'C-Допущения'!$B$25:$B$30,0),1)) -> 120000 | F7: =IF($D7="","",$D7*INDEX('C-Допущения'!$C$25:$G$30,MATCH($C7,'C-Допущения'!$B$25:$B$30,0),2)) -> 169705.63 | G7: =IF($D7="","",$D7*INDEX('C-Допущения'!$C$25:$G$30,MATCH($C7,'C-Допущения'!$B$25:$B$30,0),3)) -> 240000 | H7: =IF($D7="","",$D7*INDEX('C-Допущения'!$C$25:$G$30,MATCH($C7,'C-Допущения'!$B$25:$B$30,0),4)) -> 317490.16 | I7: =IF($D7="","",$D7*INDEX('C-Допущения'!$C$25:$G$30,MATCH($C7,'C-Допущения'!$B$25:$B$30,0),5)) -> 379473.32 | J7: =SUM(E7:I7) -> 1226669.1 | L7: Три кластера и несколько облачных провайдеров по предложению технического директора.
B8: Платформа Oracle и вычислительные ресурсы СУБД | C8: мощность | D8: 96000 | E8: =IF($D8="","",$D8*INDEX('C-Допущения'!$C$25:$G$30,MATCH($C8,'C-Допущения'!$B$25:$B$30,0),1)) -> 96000 | F8: =IF($D8="","",$D8*INDEX('C-Допущения'!$C$25:$G$30,MATCH($C8,'C-Допущения'!$B$25:$B$30,0),2)) -> 135764.5 | G8: =IF($D8="","",$D8*INDEX('C-Допущения'!$C$25:$G$30,MATCH($C8,'C-Допущения'!$B$25:$B$30,0),3)) -> 192000 | H8: =IF($D8="","",$D8*INDEX('C-Допущения'!$C$25:$G$30,MATCH($C8,'C-Допущения'!$B$25:$B$30,0),4)) -> 253992.13 | I8: =IF($D8="","",$D8*INDEX('C-Допущения'!$C$25:$G$30,MATCH($C8,'C-Допущения'!$B$25:$B$30,0),5)) -> 303578.66 | J8: =SUM(E8:I8) -> 981335.28 | L8: Резерв на самостоятельно эксплуатируемое транзакционное ядро.
B9: Объектное хранилище и резервные копии | C9: мощность | D9: 18000 | E9: =IF($D9="","",$D9*INDEX('C-Допущения'!$C$25:$G$30,MATCH($C9,'C-Допущения'!$B$25:$B$30,0),1)) -> 18000 | F9: =IF($D9="","",$D9*INDEX('C-Допущения'!$C$25:$G$30,MATCH($C9,'C-Допущения'!$B$25:$B$30,0),2)) -> 25455.844 | G9: =IF($D9="","",$D9*INDEX('C-Допущения'!$C$25:$G$30,MATCH($C9,'C-Допущения'!$B$25:$B$30,0),3)) -> 36000 | H9: =IF($D9="","",$D9*INDEX('C-Допущения'!$C$25:$G$30,MATCH($C9,'C-Допущения'!$B$25:$B$30,0),4)) -> 47623.524 | I9: =IF($D9="","",$D9*INDEX('C-Допущения'!$C$25:$G$30,MATCH($C9,'C-Допущения'!$B$25:$B$30,0),5)) -> 56920.998 | J9: =SUM(E9:I9) -> 184000.37 | L9: Резервные копии для нескольких кластеров.
B10: Сеть доставки содержимого (CDN) и исходящий трафик | C10: нагрузка заказов | D10: 12000 | E10: =IF($D10="","",$D10*INDEX('C-Допущения'!$C$25:$G$30,MATCH($C10,'C-Допущения'!$B$25:$B$30,0),1)) -> 12000 | F10: =IF($D10="","",$D10*INDEX('C-Допущения'!$C$25:$G$30,MATCH($C10,'C-Допущения'!$B$25:$B$30,0),2)) -> 29393.877 | G10: =IF($D10="","",$D10*INDEX('C-Допущения'!$C$25:$G$30,MATCH($C10,'C-Допущения'!$B$25:$B$30,0),3)) -> 53665.631 | H10: =IF($D10="","",$D10*INDEX('C-Допущения'!$C$25:$G$30,MATCH($C10,'C-Допущения'!$B$25:$B$30,0),4)) -> 75894.664 | I10: =IF($D10="","",$D10*INDEX('C-Допущения'!$C$25:$G$30,MATCH($C10,'C-Допущения'!$B$25:$B$30,0),5)) -> 92951.6 | J10: =SUM(E10:I10) -> 263905.77 | L10: Мобильные изображения и межрегиональный исходящий трафик.
B11: Самостоятельно эксплуатируемый кластер Apache Kafka | C11: мощность | D11: 48000 | E11: =IF($D11="","",$D11*INDEX('C-Допущения'!$C$25:$G$30,MATCH($C11,'C-Допущения'!$B$25:$B$30,0),1)) -> 48000 | F11: =IF($D11="","",$D11*INDEX('C-Допущения'!$C$25:$G$30,MATCH($C11,'C-Допущения'!$B$25:$B$30,0),2)) -> 67882.251 | G11: =IF($D11="","",$D11*INDEX('C-Допущения'!$C$25:$G$30,MATCH($C11,'C-Допущения'!$B$25:$B$30,0),3)) -> 96000 | H11: =IF($D11="","",$D11*INDEX('C-Допущения'!$C$25:$G$30,MATCH($C11,'C-Допущения'!$B$25:$B$30,0),4)) -> 126996.06 | I11: =IF($D11="","",$D11*INDEX('C-Допущения'!$C$25:$G$30,MATCH($C11,'C-Допущения'!$B$25:$B$30,0),5)) -> 151789.33 | J11: =SUM(E11:I11) -> 490667.64 | L11: Вычислительные ресурсы и хранилище кластера Kafka.
B12: Резервирование «активный — активный» | C12: мощность | D12: 120000 | E12: =IF($D12="","",$D12*INDEX('C-Допущения'!$C$25:$G$30,MATCH($C12,'C-Допущения'!$B$25:$B$30,0),1)) -> 120000 | F12: =IF($D12="","",$D12*INDEX('C-Допущения'!$C$25:$G$30,MATCH($C12,'C-Допущения'!$B$25:$B$30,0),2)) -> 169705.63 | G12: =IF($D12="","",$D12*INDEX('C-Допущения'!$C$25:$G$30,MATCH($C12,'C-Допущения'!$B$25:$B$30,0),3)) -> 240000 | H12: =IF($D12="","",$D12*INDEX('C-Допущения'!$C$25:$G$30,MATCH($C12,'C-Допущения'!$B$25:$B$30,0),4)) -> 317490.16 | I12: =IF($D12="","",$D12*INDEX('C-Допущения'!$C$25:$G$30,MATCH($C12,'C-Допущения'!$B$25:$B$30,0),5)) -> 379473.32 | J12: =SUM(E12:I12) -> 1226669.1 | L12: Полная межрегиональная мощность с первого дня.
